var g = function* () {
  try {
    yield;
  } catch (e) {
    console.log('内部捕获', e);
  }
};

var i = g();
i.next();

try {
  i.throw('a');
  i.throw('b');
} catch (e) {
  console.log('外部捕获', e);
}
// 内部捕获 a
// 外部捕获 b

var g = function* () {
  try {
    yield;
  } catch (e) {
    console.log(e);
  }
};

var i = g();
i.next();
i.throw(new Error('出错了！'));
// Error: 出错了！(…)

var g = function* () {
  while (true) {
    try {
      yield;
    } catch (e) {
      if (e != 'a') throw e;
      console.log('内部捕获', e);
    }
  }
};

var i = g();
i.next();

try {
  throw new Error('a');
  throw new Error('b');
} catch (e) {
  console.log('外部捕获', e);
}
// 外部捕获 [Error: a]


var g = function* () {
  while (true) {
    yield;
    console.log('内部捕获', e);
  }
};

var i = g();
i.next();

try {
  i.throw('a');
  i.throw('b');
} catch (e) {
  console.log('外部捕获', e);
}
// 外部捕获 a


var gen = function* gen(){
  yield console.log('hello');
  yield console.log('world');
}

var g = gen();
g.next();
g.throw();
// hello
// Uncaught undefined


function* gen() {
  try {
    yield 1;
  } catch (e) {
    console.log('内部捕获');
  }
}

var g = gen();
g.throw(1);
// Uncaught 1


var gen = function* gen(){
  try {
    yield 1;
  } catch (e) {
    yield 2;
  }
  yield 3;
}

var g = gen();
g.next() // { value:1, done:false }
g.throw() // { value:2, done:false }
g.next() // { value:3, done:false }
g.next() // { value:undefined, done:true }


var gen = function* gen(){
  yield console.log('hello');
  yield console.log('world');
}

var g = gen();
g.next();

try {
  throw new Error();
} catch (e) {
  g.next();
}
// hello
// world


function* foo() {
  var x = yield 3;
  var y = x.toUpperCase();
  yield y;
}

var it = foo();

it.next(); // { value:3, done:false }

try {
  it.next(42);
} catch (err) {
  console.log(err);
}


function* g() {
  yield 1;
  console.log('throwing an exception');
  throw new Error('generator broke!');
  yield 2;
  yield 3;
}

function log(generator) {
  var v;
  console.log('starting generator');
  try {
    v = generator.next();
    console.log('第一次运行next方法', v);
  } catch (err) {
    console.log('捕捉错误', v);
  }
  try {
    v = generator.next();
    console.log('第二次运行next方法', v);
  } catch (err) {
    console.log('捕捉错误', v);
  }
  try {
    v = generator.next();
    console.log('第三次运行next方法', v);
  } catch (err) {
    console.log('捕捉错误', v);
  }
  console.log('caller done');
}

log(g());
// starting generator
// 第一次运行next方法 { value: 1, done: false }
// throwing an exception
// 捕捉错误 { value: 1, done: false }
// 第三次运行next方法 { value: undefined, done: true }
// caller done